<?xml version="1.0" encoding="utf-8"?>
<!-- This URDF was automatically created by SolidWorks to URDF Exporter! Originally created by Stephen Brawner (brawner@gmail.com) 
     Commit Version: 1.6.0-4-g7f85cfe  Build Version: 1.6.7995.38578
     For more information, please see http://wiki.ros.org/sw_urdf_exporter -->
<robot
  name="5DOF">
  <link name="world"/>
  <joint name="world_to_thor1" type="fixed">
    <parent link="world"/>
    <child link="base_link"/>
    <origin xyz="-0.052 -0.2125 0" rpy="0 0 3.1415"/>
    <axis   xyz="0 0 1"/>
  </joint>
  
    <link name="map"/>
  <joint name="world_to_map" type="fixed">
    <parent link="world"/>
    <child link="map"/>
    <origin xyz="0 0 0" rpy="0 0 0"/>
  </joint>
  
  <link name="tip"/>
  <joint name="Link5_to_tip" type="fixed">
    <parent link="Link5"/>
    <child link="tip"/>
    <origin xyz="0 0 0" rpy="0 0 0"/>
  </joint>
  
  <link
    name="base_link">
    <inertial>
      <origin
        xyz="0.1016 0.00320411469759873 0.0508"
        rpy="0 0 0" />
      <mass
        value="0.127147471977805" />
      <inertia
        ixx="0.000111831356264364"
        ixy="-2.72450714762173E-22"
        ixz="-2.7400357790819E-21"
        iyy="0.000561119002312225"
        iyz="3.57128977824887E-22"
        izz="0.000450144258992043" />
    </inertial>
    <visual>
      <origin
        xyz="0 0 0"
        rpy="0 0 0" />
      <geometry>
        <mesh
          filename="package://5DOF/meshes/base_link.STL" />
      </geometry>
      <material
        name="">
        <color
          rgba="0.792156862745098 0.819607843137255 0.933333333333333 1" />
      </material>
    </visual>
    <collision>
      <origin
        xyz="0 0 0"
        rpy="0 0 0" />
      <geometry>
        <mesh
          filename="package://5DOF/meshes/base_link.STL" />
      </geometry>
    </collision>
  </link>
  <link
    name="Link1">
    <visual>
      <origin
        xyz="0 0 0"
        rpy="0 0 0" />
      <geometry>
        <mesh
          filename="package://5DOF/meshes/Link1.STL" />
      </geometry>
      <material
        name="">
        <color
          rgba="0.792156862745098 0.819607843137255 0.933333333333333 1" />
      </material>
    </visual>
  </link>
  
  <joint
    name="Thor/1"
    type="continuous">
    <origin
      xyz="-0.052 -0.2125 0" 
      rpy="1.5708 0 0" />
    <parent
      link="world" />
    <child
      link="Link1" />
    <axis
      xyz="0 1 0" />
  </joint>
  
  <link
    name="Link2">
    <visual>
      <origin
        xyz="0 0 0"
        rpy="0 0 0" />
      <geometry>
        <mesh
          filename="package://5DOF/meshes/Link2.STL" />
      </geometry>
      <material
        name="">
        <color
          rgba="0.792156862745098 0.819607843137255 0.933333333333333 1" />
      </material>
    </visual>
  </link>
  <joint
    name="Thor/6"
    type="continuous">
    <origin
      xyz="0.00016534 0.050763 0.0019121"
      rpy="-1.5708 -1.5708 -1.5708" />
    <parent
      link="Link1" />
    <child
      link="Link2" />
    <axis
      xyz="0 0 1" />
  </joint>
  <link
    name="Link3">
    <visual>
      <origin
        xyz="0 0 0"
        rpy="0 0 0" />
      <geometry>
        <mesh
          filename="package://5DOF/meshes/Link3.STL" />
      </geometry>
      <material
        name="">
        <color
          rgba="0.792156862745098 0.819607843137255 0.933333333333333 1" />
      </material>
    </visual>
  </link>
  <joint
    name="Thor/3"
    type="continuous">
    <origin
      xyz="-0.2774 0 -0.015403"
      rpy="1.5708 0 0" />
    <parent
      link="Link2" />
    <child
      link="Link3" />
    <axis
      xyz="0 -1 0" />
  </joint>
  <link
    name="Link4">
    <visual>
      <origin
        xyz="0 0 0"
        rpy="0 0 0" />
      <geometry>
        <mesh
          filename="package://5DOF/meshes/Link4.STL" />
      </geometry>
      <material
        name="">
        <color
          rgba="0.792156862745098 0.819607843137255 0.933333333333333 1" />
      </material>
    </visual>
  </link>
  <joint
    name="Thor/4"
    type="continuous">
    <origin
      xyz="-0.30216 -0.052613 0.00078978"
      rpy="0 3.1415 0" />
    <parent
      link="Link3" />
    <child
      link="Link4" />
    <axis
      xyz="0 1 0" />
  </joint>
  <link
    name="Link5">
    <visual>
      <origin
        xyz="0 0 0"
        rpy="0 0 0" />
      <geometry>
        <mesh
          filename="package://5DOF/meshes/Link5.STL" />
      </geometry>
      <material
        name="">
        <color
          rgba="0.752941176470588 0.752941176470588 0.752941176470588 1" />
      </material>
    </visual>
  </link>
  <joint
    name="Thor/2"
    type="continuous">
    <origin
      xyz="-0.0019997 -0.031718 0.072325"
      rpy="0 0 0" />
    <parent
      link="Link4" />
    <child
      link="Link5" />
    <axis
      xyz="0 0 1" />
  </joint>
</robot>
